tests/medium-example3.in
# 3 threads, 1 instrument
3
0-2 o
.
0 B 1 AAPL 15627 131
0 S 2 AAPL 790 793
1 B 3 AAPL 2866 877
0 S 4 AAPL 13053 229
0 B 5 AAPL 93 555
2 B 6 AAPL 8374 720
0 B 7 AAPL 2672 308
2 B 8 AAPL 18413 256
2 S 9 AAPL 9102 673
0 B 10 AAPL 13924 776
0 S 11 AAPL 3214 297
0 B 12 AAPL 1134 376
0 S 13 AAPL 14466 724
1 S 14 AAPL 10877 273
0 S 15 AAPL 4423 121
2 S 16 AAPL 1765 579
1 B 17 AAPL 16300 408
2 S 18 AAPL 2334 585
1 S 19 AAPL 10679 13
2 S 20 AAPL 18185 623
0 B 21 AAPL 14463 219
2 B 22 AAPL 8030 382
2 S 23 AAPL 9613 537
1 B 24 AAPL 9333 182
1 B 25 AAPL 6171 468
1 B 26 AAPL 7130 422
1 S 27 AAPL 11998 742
2 S 28 AAPL 15307 538
1 B 29 AAPL 2372 195
1 B 30 AAPL 7761 284
2 S 31 AAPL 14339 836
2 S 32 AAPL 11308 982
0 B 33 AAPL 5925 998
0 B 34 AAPL 19880 57
2 B 35 AAPL 8840 516
2 S 36 AAPL 13229 41
1 S 37 AAPL 16697 276
0 B 38 AAPL 11229 767
1 B 39 AAPL 11594 941
0 B 40 AAPL 17629 439
0 B 41 AAPL 1703 296
1 S 42 AAPL 4742 543
1 S 43 AAPL 17367 816
1 S 44 AAPL 3581 293
0 B 45 AAPL 17634 563
1 S 46 AAPL 5704 613
1 B 47 AAPL 19401 294
0 B 48 AAPL 11056 708
2 B 49 AAPL 15146 253
0 S 50 AAPL 10906 924
2 S 51 AAPL 2236 882
1 B 52 AAPL 8717 459
1 B 53 AAPL 9961 816
1 B 54 AAPL 3599 544
2 B 55 AAPL 18482 549
1 S 56 AAPL 18504 713
2 B 57 AAPL 12672 267
2 S 58 AAPL 16347 819
1 S 59 AAPL 649 501
1 S 60 AAPL 19070 462
2 B 61 AAPL 14789 602
0 B 62 AAPL 11714 371
0 B 63 AAPL 714 134
1 B 64 AAPL 6874 890
1 S 65 AAPL 6002 110
2 B 66 AAPL 15730 61
0 S 67 AAPL 15551 577
1 S 68 AAPL 13723 926
2 S 69 AAPL 268 373
2 S 70 AAPL 176 630
0 S 71 AAPL 6924 837
0 S 72 AAPL 6780 906
1 B 73 AAPL 1313 542
0 B 74 AAPL 11628 824
2 B 75 AAPL 14495 979
0 B 76 AAPL 6435 221
1 S 77 AAPL 8012 610
1 B 78 AAPL 16919 884
0 B 79 AAPL 19684 470
1 B 80 AAPL 15211 267
1 S 81 AAPL 12498 736
2 S 82 AAPL 12585 572
0 S 83 AAPL 11583 754
0 S 84 AAPL 5273 140
2 S 85 AAPL 2866 31
1 S 86 AAPL 16068 382
2 S 87 AAPL 199 399
2 S 88 AAPL 15137 604
0 B 89 AAPL 18741 46
0 B 90 AAPL 17165 816
0 B 91 AAPL 13802 745
1 S 92 AAPL 7480 399
2 B 93 AAPL 19586 856
2 S 94 AAPL 5755 955
1 B 95 AAPL 1264 69
1 B 96 AAPL 16227 876
1 B 97 AAPL 6178 770
0 S 98 AAPL 6914 856
1 B 99 AAPL 19997 111
0 S 100 AAPL 733 229
0 B 101 AAPL 10679 59
1 B 102 AAPL 15005 911
2 B 103 AAPL 9112 776
2 S 104 AAPL 6297 906
1 B 105 AAPL 9749 214
0 B 106 AAPL 4128 281
0 S 107 AAPL 361 369
0 B 108 AAPL 6851 322
2 S 109 AAPL 14391 1
2 B 110 AAPL 16441 664
2 B 111 AAPL 14511 940
1 S 112 AAPL 17389 761
2 B 113 AAPL 1399 531
0 B 114 AAPL 5055 816
0 S 115 AAPL 7972 265
1 B 116 AAPL 19896 623
1 S 117 AAPL 2952 906
0 S 118 AAPL 18724 131
0 S 119 AAPL 6595 663
0 S 120 AAPL 19883 281
0 B 121 AAPL 10052 278
2 B 122 AAPL 1178 26
1 B 123 AAPL 11756 45
0 B 124 AAPL 2204 334
0 B 125 AAPL 3517 562
0 S 126 AAPL 17975 94
1 S 127 AAPL 11792 478
0 S 128 AAPL 138 736
1 S 129 AAPL 15644 632
2 S 130 AAPL 6054 577
2 B 131 AAPL 13759 85
2 B 132 AAPL 18794 219
0 B 133 AAPL 14335 490
0 S 134 AAPL 6541 5
0 S 135 AAPL 3494 928
1 B 136 AAPL 16413 122
1 B 137 AAPL 16488 838
1 S 138 AAPL 2997 171
0 S 139 AAPL 6575 426
0 B 140 AAPL 1987 514
1 S 141 AAPL 5892 909
1 B 142 AAPL 11584 1
1 B 143 AAPL 1338 65
0 S 144 AAPL 14747 999
1 B 145 AAPL 17155 675
1 B 146 AAPL 909 722
1 S 147 AAPL 18757 933
0 S 148 AAPL 8721 617
0 S 149 AAPL 6243 752
1 B 150 AAPL 5776 236
1 B 151 AAPL 19300 347
1 B 152 AAPL 17743 173
2 S 153 AAPL 7041 974
1 S 154 AAPL 8904 470
0 S 155 AAPL 5593 894
2 S 156 AAPL 13672 555
1 B 157 AAPL 2077 573
0 B 158 AAPL 9355 2
2 S 159 AAPL 162 482
2 S 160 AAPL 2220 641
2 B 161 AAPL 17970 106
0 S 162 AAPL 1691 602
2 B 163 AAPL 2952 376
0 S 164 AAPL 15936 288
2 B 165 AAPL 4750 535
2 B 166 AAPL 13134 164
2 S 167 AAPL 566 794
0 S 168 AAPL 7825 481
1 S 169 AAPL 12883 424
2 B 170 AAPL 12724 971
0 S 171 AAPL 18300 45
2 S 172 AAPL 17572 386
1 S 173 AAPL 6597 533
2 B 174 AAPL 1486 677
1 S 175 AAPL 17291 335
2 B 176 AAPL 13488 348
0 S 177 AAPL 7586 753
2 S 178 AAPL 2860 21
2 S 179 AAPL 8236 477
2 S 180 AAPL 16690 656
2 B 181 AAPL 9508 602
1 B 182 AAPL 6525 226
0 S 183 AAPL 17302 773
0 B 184 AAPL 7631 385
0 B 185 AAPL 6818 739
2 B 186 AAPL 18847 240
2 S 187 AAPL 7854 379
0 B 188 AAPL 3693 803
2 S 189 AAPL 18343 960
0 B 190 AAPL 9430 737
2 B 191 AAPL 15545 99
2 S 192 AAPL 5413 423
1 S 193 AAPL 11882 668
1 S 194 AAPL 15643 753
1 B 195 AAPL 14470 995
0 B 196 AAPL 11500 947
1 B 197 AAPL 14735 654
2 B 198 AAPL 7267 910
0 S 199 AAPL 15491 518
1 B 200 AAPL 18520 65
1 S 201 AAPL 4375 995
2 B 202 AAPL 15067 901
0 S 203 AAPL 6037 370
0 S 204 AAPL 16463 817
1 B 205 AAPL 14933 882
0 S 206 AAPL 10777 395
0 S 207 AAPL 8307 953
1 S 208 AAPL 13306 31
2 B 209 AAPL 1458 706
1 S 210 AAPL 14933 529
1 S 211 AAPL 1928 876
0 S 212 AAPL 282 323
0 B 213 AAPL 18051 827
0 B 214 AAPL 18988 813
0 B 215 AAPL 3338 568
1 S 216 AAPL 10399 278
0 S 217 AAPL 9166 260
0 B 218 AAPL 11985 61
2 S 219 AAPL 19475 787
1 B 220 AAPL 4153 955
0 S 221 AAPL 13361 338
1 S 222 AAPL 17629 161
2 S 223 AAPL 4259 712
2 B 224 AAPL 15385 345
1 B 225 AAPL 6630 224
1 S 226 AAPL 1461 724
0 B 227 AAPL 6387 108
2 B 228 AAPL 1159 94
2 S 229 AAPL 3508 43
1 B 230 AAPL 14729 840
0 S 231 AAPL 16814 813
0 B 232 AAPL 14050 461
2 B 233 AAPL 18324 130
1 S 234 AAPL 14432 994
1 S 235 AAPL 12431 12
1 S 236 AAPL 18355 398
1 S 237 AAPL 18890 294
1 S 238 AAPL 17137 989
2 S 239 AAPL 9419 351
2 B 240 AAPL 4033 114
0 S 241 AAPL 18596 672
1 B 242 AAPL 8502 440
1 S 243 AAPL 16066 905
2 B 244 AAPL 3208 490
1 B 245 AAPL 12260 894
1 S 246 AAPL 17183 736
1 B 247 AAPL 17965 491
1 S 248 AAPL 13433 483
1 S 249 AAPL 19016 213
1 B 250 AAPL 18163 407
1 S 251 AAPL 14857 197
0 B 252 AAPL 1790 529
2 B 253 AAPL 11954 333
2 B 254 AAPL 7190 718
0 S 255 AAPL 4607 784
0 S 256 AAPL 16481 978
1 S 257 AAPL 15226 805
2 S 258 AAPL 10041 454
0 B 259 AAPL 18924 34
1 B 260 AAPL 1467 522
0 B 261 AAPL 15538 800
0 B 262 AAPL 2904 489
0 B 263 AAPL 13345 261
2 S 264 AAPL 10306 272
0 B 265 AAPL 2352 689
2 B 266 AAPL 1056 897
1 B 267 AAPL 5128 35
2 S 268 AAPL 5392 349
1 S 269 AAPL 3804 813
2 B 270 AAPL 10329 777
0 B 271 AAPL 7592 225
0 B 272 AAPL 10292 379
0 B 273 AAPL 14354 100
0 B 274 AAPL 1983 345
1 B 275 AAPL 12933 440
2 B 276 AAPL 11825 652
1 B 277 AAPL 972 250
1 S 278 AAPL 13092 559
2 S 279 AAPL 13422 421
1 S 280 AAPL 45 135
1 B 281 AAPL 5385 369
2 B 282 AAPL 58 143
1 B 283 AAPL 19489 392
0 S 284 AAPL 9921 902
0 B 285 AAPL 2454 43
1 B 286 AAPL 9309 582
1 B 287 AAPL 578 251
0 B 288 AAPL 6110 851
2 S 289 AAPL 4474 358
2 B 290 AAPL 19658 278
2 B 291 AAPL 2024 85
2 B 292 AAPL 11296 813
0 S 293 AAPL 8961 693
1 B 294 AAPL 3815 479
1 S 295 AAPL 10065 20
2 B 296 AAPL 1408 873
1 B 297 AAPL 7516 466
2 B 298 AAPL 19052 529
1 B 299 AAPL 2245 431
0 B 300 AAPL 12180 17
1 S 301 AAPL 5934 224
1 S 302 AAPL 2828 308
2 B 303 AAPL 13095 165
2 B 304 AAPL 19617 964
2 B 305 AAPL 1490 27
0 B 306 AAPL 3100 579
0 B 307 AAPL 1136 87
2 S 308 AAPL 19767 972
0 S 309 AAPL 19152 245
0 S 310 AAPL 9493 692
2 S 311 AAPL 4168 35
0 B 312 AAPL 17181 451
1 B 313 AAPL 2205 937
0 B 314 AAPL 10379 902
0 S 315 AAPL 11900 723
2 B 316 AAPL 5583 910
1 S 317 AAPL 15333 122
1 B 318 AAPL 4482 176
0 B 319 AAPL 13268 862
1 S 320 AAPL 7869 883
0 S 321 AAPL 3831 798
0 B 322 AAPL 19523 807
2 S 323 AAPL 15096 217
0 S 324 AAPL 9431 230
2 S 325 AAPL 13938 235
2 B 326 AAPL 19653 130
0 S 327 AAPL 14871 99
2 B 328 AAPL 3373 946
0 S 329 AAPL 1493 275
1 S 330 AAPL 7190 266
0 B 331 AAPL 12424 33
0 S 332 AAPL 11235 152
2 S 333 AAPL 7546 252
2 S 334 AAPL 17633 768
2 S 335 AAPL 19862 929
1 S 336 AAPL 2395 468
2 S 337 AAPL 4143 535
1 B 338 AAPL 2960 583
1 S 339 AAPL 4472 867
0 S 340 AAPL 6808 355
1 S 341 AAPL 11987 118
0 B 342 AAPL 1056 139
0 S 343 AAPL 190 383
0 S 344 AAPL 17830 411
2 B 345 AAPL 13023 119
1 B 346 AAPL 10053 805
2 S 347 AAPL 3657 818
1 B 348 AAPL 16826 466
1 S 349 AAPL 14003 31
0 S 350 AAPL 8992 370
0 S 351 AAPL 17711 478
2 B 352 AAPL 18030 183
1 B 353 AAPL 16670 110
0 S 354 AAPL 11857 30
1 S 355 AAPL 4052 959
2 B 356 AAPL 2896 277
1 S 357 AAPL 9953 168
1 S 358 AAPL 8541 930
1 S 359 AAPL 7277 90
0 B 360 AAPL 11756 116
2 B 361 AAPL 12647 251
1 S 362 AAPL 9258 728
